
<mujoco model="cantilever_3d_drone">
    <compiler angle="degree" inertiafromgeom="true" coordinate="local"/>
    <option timestep="0.01" gravity="0 0 -9.81" density="1" viscosity="1e-5" integrator="RK4"/>

    <default>
        <!-- Un poco de amortiguamiento para estabilidad -->
        <joint damping="0.001" limited="false"/>
        <geom conaffinity="0" condim="3" density="500" friction="1 0.5 0.5" margin="0.01" rgba="0.8 0.6 0.4 1"/>
    </default>

    <asset>
        <texture builtin="gradient" type="skybox" height="100" width="100" rgb1="1 1 1" rgb2="0.6 0.8 1"/>
        <texture name="texplane" builtin="checker" height="100" width="100" rgb1="0.7 0.7 0.7" rgb2="0.9 0.9 0.9" type="2d"/>
        <material name="MatPlane" reflectance="0.3" shininess="1" specular="0.5" texrepeat="5 5" texture="texplane"/>
        <material name="MatBeam" specular="0.3" shininess="0.5" rgba="0.3 0.7 0.3 1"/>
        <material name="MatDrone" specular="0.5" shininess="1" rgba="0.8 0.2 0.2 1"/>
    </asset>

    <worldbody>
        <light cutoff="100" diffuse="1 1 1" dir="-0 0 -1.3" directional="true" exponent="1" pos="0 0 1.3" specular=".1 .1 .1"/>
        <geom conaffinity="1" condim="3" material="MatPlane" name="floor" pos="0 0 0" rgba="0.4 0.3 0.3 1" size="5 5 0.2" type="plane"/>
        <geom name="wall" type="box" size="0.05 0.05 0.15" pos="0 0 0.25" rgba="0.2 0.3 0.8 1"/>

        <!-- âš™ï¸ Base fija de la viga -->
        <body name="beam_base" pos="0.05 0 1.0">
            <!-- Sitio de referencia del soporte -->
            <site name="base_site" pos="0 0 0" size="0.01" rgba="1 0 0 1"/>
            <!-- ðŸ”— Barra flexible 3D con 6 segmentos -->
            <body name="seg1" pos="0.1 0 0">
                <joint name="ball1" type="ball" damping="0.002"/>
                <geom type="capsule" fromto="0 0 0 0.200 0 0" size="0.01" material="MatBeam" mass="0.017"/>
                <body name="seg2" pos="0.200 0 0">
                    <joint name="ball2" type="ball" damping="0.002"/>
                    <geom type="capsule" fromto="0 0 0 0.200 0 0" size="0.01" rgba="0.3 0.74 0.46 1" mass="0.017"/>
                <body name="seg3" pos="0.200 0 0">
                    <joint name="ball3" type="ball" damping="0.002"/>
                    <geom type="capsule" fromto="0 0 0 0.200 0 0" size="0.01" rgba="0.3 0.66 0.54 1" mass="0.017"/>
                <body name="seg4" pos="0.200 0 0">
                    <joint name="ball4" type="ball" damping="0.002"/>
                    <geom type="capsule" fromto="0 0 0 0.200 0 0" size="0.01" rgba="0.3 0.58 0.62 1" mass="0.017"/>
                <body name="seg5" pos="0.200 0 0">
                    <joint name="ball5" type="ball" damping="0.002"/>
                    <geom type="capsule" fromto="0 0 0 0.200 0 0" size="0.01" rgba="0.3 0.50 0.70 1" mass="0.017"/>
                <body name="seg6" pos="0.200 0 0">
                    <joint name="ball6" type="ball" damping="0.002"/>
                    <geom type="capsule" fromto="0 0 0 0.200 0 0" size="0.01" rgba="0.3 0.42 0.78 1" mass="0.017"/>
                    <!-- Punto de conexiÃ³n (extremo libre) -->
                    <site name="end_site" pos="0.200 0 0" size="0.01" rgba="1 1 0 1"/>
                    <!-- Dron cerca del extremo, se une con connect(ball) -->
                    <body name="drone_mount" pos="0.200 0 0.02">

                        <!-- ðŸš Dron 3D (cuerpo libre) -->
                        <body name="drone_3d" pos="0 0 0">
                            <!-- Joint libre (6DOF): permite que el dron exista fÃ­sicamente en 3D -->
                            <joint name="drone_free" type="free"/>

                            <!-- Cuerpo principal -->
                            <geom name="drone_body" type="box" size="0.08 0.04 0.02" material="MatDrone" mass="0.15"/>

                            <!-- Brazos (solo visual/simple) -->
                            <geom name="arm_x_pos" type="box" pos=" 0.10 0 0" size="0.06 0.01 0.01" rgba="0.8 0.8 0.8 1"/>
                            <geom name="arm_x_neg" type="box" pos="-0.10 0 0" size="0.06 0.01 0.01" rgba="0.8 0.8 0.8 1"/>
                            <geom name="arm_y_pos" type="box" pos="0  0.10 0" size="0.01 0.06 0.01" rgba="0.8 0.8 0.8 1"/>
                            <geom name="arm_y_neg" type="box" pos="0 -0.10 0" size="0.01 0.06 0.01" rgba="0.8 0.8 0.8 1"/>

                            <!-- HÃ©lices / motores (sites para actuadores) -->
                            <body name="prop_0" pos=" 0.13  0.00 0.03">
                                <geom type="cylinder" size="0.02 0.003" rgba="0.3 1 0.3 0.6"/>
                                <site name="motor_0" pos="0 0 0.003" size="0.006" rgba="0 1 0 0.7" type="cylinder"/>
                            </body>
                            <body name="prop_1" pos="-0.13  0.00 0.03">
                                <geom type="cylinder" size="0.02 0.003" rgba="0.3 1 0.3 0.6"/>
                                <site name="motor_1" pos="0 0 0.003" size="0.006" rgba="0 1 0 0.7" type="cylinder"/>
                            </body>
                            <body name="prop_2" pos=" 0.00  0.13 0.03">
                                <geom type="cylinder" size="0.02 0.003" rgba="0.3 1 0.3 0.6"/>
                                <site name="motor_2" pos="0 0 0.003" size="0.006" rgba="0 1 0 0.7" type="cylinder"/>
                            </body>
                            <body name="prop_3" pos=" 0.00 -0.13 0.03">
                                <geom type="cylinder" size="0.02 0.003" rgba="0.3 1 0.3 0.6"/>
                                <site name="motor_3" pos="0 0 0.003" size="0.006" rgba="0 1 0 0.7" type="cylinder"/>
                            </body>

                            <!-- Sitio donde se conecta la rÃ³tula (ball) con la viga -->
                            <site name="drone_attach" pos="0 0 0" size="0.01" rgba="1 0 1 1"/>

                            <!-- Ejes de referencia -->
                            <site name="x_axis" type="box" pos="0.20 0 0" size="0.20 0.005 0.005" rgba="1 0 0 0.3"/>
                            <site name="y_axis" type="box" pos="0 0.20 0" size="0.005 0.20 0.005" rgba="0 1 0 0.3"/>
                            <site name="z_axis" type="box" pos="0 0 0.20" size="0.005 0.005 0.20" rgba="0 0 1 0.3"/>
                        </body>

                    </body>
                </body>
                </body>
                </body>
                </body>
                </body>
            </body>
        </body>
    </worldbody>

    <!-- âš™ï¸ Actuadores (4 hÃ©lices) -->
    <actuator>
        <!-- ctrlrange mÃ¡s amplio para que sea mÃ¡s fÃ¡cil controlar -->
        <motor site="motor_0" ctrlrange="0 2" gear="0 0 1 0 0 -0.05"/>
        <motor site="motor_1" ctrlrange="0 2" gear="0 0 1 0 0  0.05"/>
        <motor site="motor_2" ctrlrange="0 2" gear="0 0 1 0 0 -0.05"/>
        <motor site="motor_3" ctrlrange="0 2" gear="0 0 1 0 0  0.05"/>
    </actuator>

    <!-- ðŸ“¡ Sensores -->
    <sensor>
        <framepos    name="pos_drone"    objtype="body" objname="drone_3d"/>
        <framequat   name="quat_drone"   objtype="body" objname="drone_3d"/>
        <framelinvel name="linvel_drone" objtype="body" objname="drone_3d"/>
        <frameangvel name="rotvel_drone" objtype="body" objname="drone_3d"/>
    </sensor>

    <!-- ðŸ§© UniÃ³n esfÃ©rica (ball) entre Ãºltimo segmento y dron -->
    <equality>
        <!-- Conecta el sitio del Ãºltimo segmento (end_site) con el sitio del dron (drone_attach)
             Esto actÃºa como una rÃ³tula: coinciden en posiciÃ³n, pero el dron puede rotar libremente -->
        <connect name="ball_to_drone" site1="end_site" site2="drone_attach"
                 solimp="0.9 0.95 0.001" solref="0.02 1"/>
    </equality>

</mujoco>
